<?xml version="1.0" encoding="UTF-8"?>
<testng-results ignored="0" total="3" passed="0" failed="3" skipped="0">
  <reporter-output>
  </reporter-output>
  <suite started-at="2021-02-02T15:31:32 CET" name="Default suite" finished-at="2021-02-02T15:32:01 CET" duration-ms="29334">
    <groups>
    </groups>
    <test started-at="2021-02-02T15:31:32 CET" name="Default test" finished-at="2021-02-02T15:32:01 CET" duration-ms="29334">
      <class name="com.qa.listeners.FailedCasesScreenshotTest">
        <test-method is-config="true" signature="setUp()[pri:0, instance:com.qa.listeners.FailedCasesScreenshotTest@1fe20588]" started-at="2021-02-02T15:31:32 CET" name="setUp" finished-at="2021-02-02T15:31:43 CET" duration-ms="10415" status="PASS">
          <reporter-output>
          </reporter-output>
        </test-method> <!-- setUp -->
        <test-method signature="takeScreenshotTest1()[pri:0, instance:com.qa.listeners.FailedCasesScreenshotTest@1fe20588]" started-at="2021-02-02T15:31:43 CET" name="takeScreenshotTest1" finished-at="2021-02-02T15:31:43 CET" duration-ms="23" status="FAIL">
          <exception class="java.lang.AssertionError">
            <message>
              <![CDATA[expected [false] but found [true]]]>
            </message>
            <full-stacktrace>
              <![CDATA[java.lang.AssertionError: expected [false] but found [true]
at org.testng.Assert.fail(Assert.java:99)
at org.testng.Assert.failNotEquals(Assert.java:1037)
at org.testng.Assert.assertEqualsImpl(Assert.java:140)
at org.testng.Assert.assertEquals(Assert.java:122)
at org.testng.Assert.assertEquals(Assert.java:819)
at org.testng.Assert.assertEquals(Assert.java:829)
at com.qa.listeners.FailedCasesScreenshotTest.takeScreenshotTest1(FailedCasesScreenshotTest.java:24)
at java.base/jdk.internal.reflect.NativeMethodAccessorImpl.invoke0(Native Method)
at java.base/jdk.internal.reflect.NativeMethodAccessorImpl.invoke(NativeMethodAccessorImpl.java:62)
at java.base/jdk.internal.reflect.DelegatingMethodAccessorImpl.invoke(DelegatingMethodAccessorImpl.java:43)
at java.base/java.lang.reflect.Method.invoke(Method.java:564)
at org.testng.internal.MethodInvocationHelper.invokeMethod(MethodInvocationHelper.java:132)
at org.testng.internal.TestInvoker.invokeMethod(TestInvoker.java:599)
at org.testng.internal.TestInvoker.invokeTestMethod(TestInvoker.java:174)
at org.testng.internal.MethodRunner.runInSequence(MethodRunner.java:46)
at org.testng.internal.TestInvoker$MethodInvocationAgent.invoke(TestInvoker.java:822)
at org.testng.internal.TestInvoker.invokeTestMethods(TestInvoker.java:147)
at org.testng.internal.TestMethodWorker.invokeTestMethods(TestMethodWorker.java:146)
at org.testng.internal.TestMethodWorker.run(TestMethodWorker.java:128)
at java.base/java.util.ArrayList.forEach(ArrayList.java:1510)
at org.testng.TestRunner.privateRun(TestRunner.java:764)
at org.testng.TestRunner.run(TestRunner.java:585)
at org.testng.SuiteRunner.runTest(SuiteRunner.java:384)
at org.testng.SuiteRunner.runSequentially(SuiteRunner.java:378)
at org.testng.SuiteRunner.privateRun(SuiteRunner.java:337)
at org.testng.SuiteRunner.run(SuiteRunner.java:286)
at org.testng.SuiteRunnerWorker.runSuite(SuiteRunnerWorker.java:53)
at org.testng.SuiteRunnerWorker.run(SuiteRunnerWorker.java:96)
at org.testng.TestNG.runSuitesSequentially(TestNG.java:1218)
at org.testng.TestNG.runSuitesLocally(TestNG.java:1140)
at org.testng.TestNG.runSuites(TestNG.java:1069)
at org.testng.TestNG.run(TestNG.java:1037)
at org.testng.remote.AbstractRemoteTestNG.run(AbstractRemoteTestNG.java:115)
at org.testng.remote.RemoteTestNG.initAndRun(RemoteTestNG.java:251)
at org.testng.remote.RemoteTestNG.main(RemoteTestNG.java:77)
]]>
            </full-stacktrace>
          </exception> <!-- java.lang.AssertionError -->
          <reporter-output>
          </reporter-output>
        </test-method> <!-- takeScreenshotTest1 -->
        <test-method is-config="true" signature="tearDown()[pri:0, instance:com.qa.listeners.FailedCasesScreenshotTest@1fe20588]" started-at="2021-02-02T15:31:43 CET" name="tearDown" finished-at="2021-02-02T15:31:45 CET" duration-ms="2241" status="PASS">
          <reporter-output>
          </reporter-output>
        </test-method> <!-- tearDown -->
        <test-method is-config="true" signature="setUp()[pri:0, instance:com.qa.listeners.FailedCasesScreenshotTest@1fe20588]" started-at="2021-02-02T15:31:45 CET" name="setUp" finished-at="2021-02-02T15:31:53 CET" duration-ms="7164" status="PASS">
          <reporter-output>
          </reporter-output>
        </test-method> <!-- setUp -->
        <test-method signature="takeScreenshotTest2()[pri:0, instance:com.qa.listeners.FailedCasesScreenshotTest@1fe20588]" started-at="2021-02-02T15:31:53 CET" name="takeScreenshotTest2" finished-at="2021-02-02T15:31:53 CET" duration-ms="3" status="FAIL">
          <exception class="java.lang.AssertionError">
            <message>
              <![CDATA[expected [false] but found [true]]]>
            </message>
            <full-stacktrace>
              <![CDATA[java.lang.AssertionError: expected [false] but found [true]
at org.testng.Assert.fail(Assert.java:99)
at org.testng.Assert.failNotEquals(Assert.java:1037)
at org.testng.Assert.assertEqualsImpl(Assert.java:140)
at org.testng.Assert.assertEquals(Assert.java:122)
at org.testng.Assert.assertEquals(Assert.java:819)
at org.testng.Assert.assertEquals(Assert.java:829)
at com.qa.listeners.FailedCasesScreenshotTest.takeScreenshotTest2(FailedCasesScreenshotTest.java:28)
at java.base/jdk.internal.reflect.NativeMethodAccessorImpl.invoke0(Native Method)
at java.base/jdk.internal.reflect.NativeMethodAccessorImpl.invoke(NativeMethodAccessorImpl.java:62)
at java.base/jdk.internal.reflect.DelegatingMethodAccessorImpl.invoke(DelegatingMethodAccessorImpl.java:43)
at java.base/java.lang.reflect.Method.invoke(Method.java:564)
at org.testng.internal.MethodInvocationHelper.invokeMethod(MethodInvocationHelper.java:132)
at org.testng.internal.TestInvoker.invokeMethod(TestInvoker.java:599)
at org.testng.internal.TestInvoker.invokeTestMethod(TestInvoker.java:174)
at org.testng.internal.MethodRunner.runInSequence(MethodRunner.java:46)
at org.testng.internal.TestInvoker$MethodInvocationAgent.invoke(TestInvoker.java:822)
at org.testng.internal.TestInvoker.invokeTestMethods(TestInvoker.java:147)
at org.testng.internal.TestMethodWorker.invokeTestMethods(TestMethodWorker.java:146)
at org.testng.internal.TestMethodWorker.run(TestMethodWorker.java:128)
at java.base/java.util.ArrayList.forEach(ArrayList.java:1510)
at org.testng.TestRunner.privateRun(TestRunner.java:764)
at org.testng.TestRunner.run(TestRunner.java:585)
at org.testng.SuiteRunner.runTest(SuiteRunner.java:384)
at org.testng.SuiteRunner.runSequentially(SuiteRunner.java:378)
at org.testng.SuiteRunner.privateRun(SuiteRunner.java:337)
at org.testng.SuiteRunner.run(SuiteRunner.java:286)
at org.testng.SuiteRunnerWorker.runSuite(SuiteRunnerWorker.java:53)
at org.testng.SuiteRunnerWorker.run(SuiteRunnerWorker.java:96)
at org.testng.TestNG.runSuitesSequentially(TestNG.java:1218)
at org.testng.TestNG.runSuitesLocally(TestNG.java:1140)
at org.testng.TestNG.runSuites(TestNG.java:1069)
at org.testng.TestNG.run(TestNG.java:1037)
at org.testng.remote.AbstractRemoteTestNG.run(AbstractRemoteTestNG.java:115)
at org.testng.remote.RemoteTestNG.initAndRun(RemoteTestNG.java:251)
at org.testng.remote.RemoteTestNG.main(RemoteTestNG.java:77)
]]>
            </full-stacktrace>
          </exception> <!-- java.lang.AssertionError -->
          <reporter-output>
          </reporter-output>
        </test-method> <!-- takeScreenshotTest2 -->
        <test-method is-config="true" signature="tearDown()[pri:0, instance:com.qa.listeners.FailedCasesScreenshotTest@1fe20588]" started-at="2021-02-02T15:31:53 CET" name="tearDown" finished-at="2021-02-02T15:31:54 CET" duration-ms="1016" status="PASS">
          <reporter-output>
          </reporter-output>
        </test-method> <!-- tearDown -->
        <test-method is-config="true" signature="setUp()[pri:0, instance:com.qa.listeners.FailedCasesScreenshotTest@1fe20588]" started-at="2021-02-02T15:31:54 CET" name="setUp" finished-at="2021-02-02T15:32:00 CET" duration-ms="6011" status="PASS">
          <reporter-output>
          </reporter-output>
        </test-method> <!-- setUp -->
        <test-method signature="takeScreenshotTest3()[pri:0, instance:com.qa.listeners.FailedCasesScreenshotTest@1fe20588]" started-at="2021-02-02T15:32:00 CET" name="takeScreenshotTest3" finished-at="2021-02-02T15:32:00 CET" duration-ms="2" status="FAIL">
          <exception class="java.lang.AssertionError">
            <message>
              <![CDATA[expected [false] but found [true]]]>
            </message>
            <full-stacktrace>
              <![CDATA[java.lang.AssertionError: expected [false] but found [true]
at org.testng.Assert.fail(Assert.java:99)
at org.testng.Assert.failNotEquals(Assert.java:1037)
at org.testng.Assert.assertEqualsImpl(Assert.java:140)
at org.testng.Assert.assertEquals(Assert.java:122)
at org.testng.Assert.assertEquals(Assert.java:819)
at org.testng.Assert.assertEquals(Assert.java:829)
at com.qa.listeners.FailedCasesScreenshotTest.takeScreenshotTest3(FailedCasesScreenshotTest.java:33)
at java.base/jdk.internal.reflect.NativeMethodAccessorImpl.invoke0(Native Method)
at java.base/jdk.internal.reflect.NativeMethodAccessorImpl.invoke(NativeMethodAccessorImpl.java:62)
at java.base/jdk.internal.reflect.DelegatingMethodAccessorImpl.invoke(DelegatingMethodAccessorImpl.java:43)
at java.base/java.lang.reflect.Method.invoke(Method.java:564)
at org.testng.internal.MethodInvocationHelper.invokeMethod(MethodInvocationHelper.java:132)
at org.testng.internal.TestInvoker.invokeMethod(TestInvoker.java:599)
at org.testng.internal.TestInvoker.invokeTestMethod(TestInvoker.java:174)
at org.testng.internal.MethodRunner.runInSequence(MethodRunner.java:46)
at org.testng.internal.TestInvoker$MethodInvocationAgent.invoke(TestInvoker.java:822)
at org.testng.internal.TestInvoker.invokeTestMethods(TestInvoker.java:147)
at org.testng.internal.TestMethodWorker.invokeTestMethods(TestMethodWorker.java:146)
at org.testng.internal.TestMethodWorker.run(TestMethodWorker.java:128)
at java.base/java.util.ArrayList.forEach(ArrayList.java:1510)
at org.testng.TestRunner.privateRun(TestRunner.java:764)
at org.testng.TestRunner.run(TestRunner.java:585)
at org.testng.SuiteRunner.runTest(SuiteRunner.java:384)
at org.testng.SuiteRunner.runSequentially(SuiteRunner.java:378)
at org.testng.SuiteRunner.privateRun(SuiteRunner.java:337)
at org.testng.SuiteRunner.run(SuiteRunner.java:286)
at org.testng.SuiteRunnerWorker.runSuite(SuiteRunnerWorker.java:53)
at org.testng.SuiteRunnerWorker.run(SuiteRunnerWorker.java:96)
at org.testng.TestNG.runSuitesSequentially(TestNG.java:1218)
at org.testng.TestNG.runSuitesLocally(TestNG.java:1140)
at org.testng.TestNG.runSuites(TestNG.java:1069)
at org.testng.TestNG.run(TestNG.java:1037)
at org.testng.remote.AbstractRemoteTestNG.run(AbstractRemoteTestNG.java:115)
at org.testng.remote.RemoteTestNG.initAndRun(RemoteTestNG.java:251)
at org.testng.remote.RemoteTestNG.main(RemoteTestNG.java:77)
]]>
            </full-stacktrace>
          </exception> <!-- java.lang.AssertionError -->
          <reporter-output>
          </reporter-output>
        </test-method> <!-- takeScreenshotTest3 -->
        <test-method is-config="true" signature="tearDown()[pri:0, instance:com.qa.listeners.FailedCasesScreenshotTest@1fe20588]" started-at="2021-02-02T15:32:00 CET" name="tearDown" finished-at="2021-02-02T15:32:01 CET" duration-ms="1006" status="PASS">
          <reporter-output>
          </reporter-output>
        </test-method> <!-- tearDown -->
      </class> <!-- com.qa.listeners.FailedCasesScreenshotTest -->
    </test> <!-- Default test -->
  </suite> <!-- Default suite -->
</testng-results>
